<?xml version="1.0" encoding="utf-8"?>
<robot
  name="sonnyV4">
  <link
    name="pelvis">
    <inertial>
      <origin xyz="-0.057791 0 -0.048345" rpy="0 0 0"/>
      <mass value="5.04973"/>
      <inertia ixx="0.044329" ixy="-0.000027" ixz="0.002091" iyy="0.010950" iyz="-0.000004" izz="0.047007"/>
    </inertial>
    <visual>
      <origin
        xyz="0 0 0"
        rpy="0 0 0" />
      <geometry>
        <mesh
          filename="../meshes/base.STL" />
      </geometry>
      <material
        name="">
        <color
          rgba="0.15 0.15 0.15 1" />
        <!-- <color
          rgba="0.752941176470588 0.752941176470588 0.752941176470588 1" /> -->
      </material>
    </visual>
    <collision>
      <origin
        xyz="-0.05 0.0 -0.05"
        rpy="1.57 0 0" />
      <geometry>
        <cylinder length="0.2" radius="0.05"/>
      </geometry>
      <!-- <origin
        xyz="0 0 0"
        rpy="0 0 0" />
      <geometry>
        <mesh
          filename="../meshes/base.STL" />
      </geometry> -->
    </collision>
  </link>
  <link
    name="hipRollLeft">
    <inertial>
      <origin xyz="0.038363 0.000079 -0.000669" rpy="0 0 0"/>
      <mass value="1.300114"/>
      <inertia ixx="0.001191" ixy="0.000001" ixz="-0.000122" iyy="0.001273" iyz="0.0000" izz="0.001434"/>
    </inertial>
    <visual>
      <origin
        xyz="0 0 0"
        rpy="0 0 0" />
      <geometry>
        <mesh
          filename="../meshes/l2.STL" />
      </geometry>
      <material
        name="">
        <color
          rgba="0.15 0.15 0.15 1" />
        <!-- <color
          rgba="0.752941176470588 0.752941176470588 0.752941176470588 1" /> -->
      </material>
    </visual>
    <!-- <collision>
      <origin
        xyz="0 0 0"
        rpy="0 0 0" />
      <geometry>
        <mesh
          filename="../meshes/l2.STL" />
      </geometry>
    </collision> -->
  </link>
  <joint
    name="hipRoll_Left"
    type="revolute">
    <origin
      xyz="-0.048 0.105 -0.0575"
      rpy="0 0 0" />
    <parent
      link="pelvis" />
    <child
      link="hipRollLeft" />
    <axis
      xyz="1 0 0" />
    <limit effort="100.0" lower="-0.0873" upper="0.5236" velocity="8.0"/>
  </joint>
  <link
    name="hipYawLeft">
    <inertial>
      <origin xyz="-0.000002 0.044064 -0.085155" rpy="0 0 0"/>
      <mass value="3.946045"/>
      <inertia ixx="0.009075" ixy="-0.000" ixz="-0.000029" iyy="0.014711" iyz="-0.000457" izz="0.008308"/>
    </inertial>
    <visual>
      <origin
        xyz="0 0 0"
        rpy="0 0 0" />
      <geometry>
        <mesh
          filename="../meshes/l3.STL" />
      </geometry>
      <material
        name="">
        <color
          rgba="0.15 0.15 0.15 1" />
        <!-- <color
          rgba="0.752941176470588 0.752941176470588 0.752941176470588 1" /> -->
      </material>
    </visual>
    <!-- <collision>
      <origin
        xyz="0 0 0"
        rpy="0 0 0" />
      <geometry>
        <mesh
          filename="../meshes/l3.STL" />
      </geometry>
    </collision> -->
  </link>
  <joint
    name="hipYaw_Left"
    type="revolute">
    <origin
      xyz="0.048 0 -0.0415"
      rpy="0 0 0" />
    <parent
      link="hipRollLeft" />
    <child
      link="hipYawLeft" />
    <axis
      xyz="0 0 1" />
    <limit effort="82.5" lower="-0.3927" upper="0.3927" velocity="8.0"/>
  </joint>
  <link
    name="thigh_Left">
    <inertial>
      <origin xyz="0.001848 -0.020822 -0.089529" rpy="0 0 0"/>
      <mass value="5.912408"/>
      <inertia ixx="0.066232" ixy="0.000184" ixz="-0.000831" iyy="0.072898" iyz="-0.005319" izz="0.012788"/>
    </inertial>
    <visual>
      <origin
        xyz="0 0 0"
        rpy="0 0 0" />
      <geometry>
        <mesh
          filename="../meshes/l4.STL" />
      </geometry>
      <material
        name="">
        <color
          rgba="0.15 0.15 0.15 1" />
        <!-- <color
          rgba="0.752941176470588 0.752941176470588 0.752941176470588 1" /> -->
      </material>
    </visual>
    <!-- <collision>
      <origin
        xyz="0 0 0"
        rpy="0 0 0" />
      <geometry>
        <mesh
          filename="../meshes/l4.STL" />
      </geometry>
    </collision> -->
  </link>
  <joint
    name="hipPitch_Left"
    type="revolute">
    <origin
      xyz="0 0 -0.089"
      rpy="0 0 0" />
    <parent
      link="hipYawLeft" />
    <child
      link="thigh_Left" />
    <axis
      xyz="0 1 0" />
    <limit effort="160.0" lower="-1.2217" upper="0.6981" velocity="15.0"/>
  </joint>
  <link
    name="shin_Left">
    <inertial>
      <origin xyz="-0.003249 0.000089 -0.125655" rpy="0 0 0"/>
      <mass value="1.596833"/>
      <inertia ixx="0.012545" ixy="-0.000006" ixz="0.000751" iyy="0.012925" iyz="0.000128" izz="0.001146"/>
    </inertial>
    <visual>
      <origin
        xyz="0 0 0"
        rpy="0 0 0" />
      <geometry>
        <mesh
          filename="../meshes/l5.STL" />
      </geometry>
      <material
        name="">
        <color
          rgba="0.15 0.15 0.15 1" />
        <!-- <color
          rgba="0.752941176470588 0.752941176470588 0.752941176470588 1" /> -->
      </material>
    </visual>
    <!-- <collision>
      <origin
        xyz="0 0 0"
        rpy="0 0 0" />
      <geometry>
        <mesh
          filename="../meshes/l5.STL" />
      </geometry>
    </collision> -->
  </link>
  <joint
    name="kneePitch_Left"
    type="revolute">
    <origin
      xyz="0.0 0.0 -0.36"
      rpy="0 0 0" />
    <parent
      link="thigh_Left" />
    <child
      link="shin_Left" />
    <axis
      xyz="0 1 0" />
    <limit effort="160.0" lower="-0.0873" upper="2.0944" velocity="15.0"/>
  </joint>
  <link
    name="footLeftY">
    <inertial>
      <origin xyz="0 0 0" rpy="0 0 0"/>
      <mass value="0.08149923"/>
      <inertia ixx="0.00001092" ixy="0" ixz="0" iyy="0.00000851" iyz="0" izz=" 0.00001392"/>
    </inertial>
    <visual>
      <origin
        xyz="0 0 0"
        rpy="0 0 0" />
      <geometry>
        <mesh
          filename="../meshes/l6.STL" />
      </geometry>
      <material
        name="">
        <color
          rgba="0.15 0.15 0.15 1" />
        <!-- <color
          rgba="0.752941176470588 0.752941176470588 0.752941176470588 1" /> -->
      </material>
    </visual>
    <!-- <collision>
      <origin
        xyz="0 0 0"
        rpy="0 0 0" />
      <geometry>
        <mesh
          filename="../meshes/l6.STL" />
      </geometry>
    </collision> -->
  </link>
  <joint
    name="anklePitch_Left"
    type="revolute">
    <origin
      xyz="0.0 0.0 -0.34"
      rpy="0 0 0" />
    <parent
      link="shin_Left" />
    <child
      link="footLeftY" />
    <axis
      xyz="0 1 0" />
    <limit effort="8.0" lower="-1.0472" upper="0.5236" velocity="20.0"/>
  </joint>
  <link
    name="toe_left">
    <inertial>
      <origin xyz="0.014092 0.00000 -0.024641" rpy="0 0 0"/>
      <mass value="0.328269"/>
      <inertia ixx="0.000125" ixy="0.0000" ixz="-0.000065" iyy="0.001089" iyz="0.00000" izz="0.001152"/>
    </inertial>
    <visual>
      <origin
        xyz="0 0 0"
        rpy="0 0 0" />
      <geometry>
        <mesh
          filename="../meshes/l7.STL" />
      </geometry>
      <material
        name="">
        <color
          rgba="0.15 0.15 0.15 1" />
        <!-- <color
          rgba="0.752941176470588 0.752941176470588 0.752941176470588 1" /> -->
      </material>
    </visual>
    <!-- <collision>
      <origin
        xyz="0 0 0"
        rpy="0 0 0" />
      <geometry>
        <mesh
          filename="../meshes/l7.STL" />
      </geometry>
    </collision> -->
    <collision name="toe1_left">
      <origin rpy="0 1.5708 0" xyz="0.03 0.015 -0.024"/>
      <geometry>
        <cylinder length="0.17" radius="0.015"/>
      </geometry>
    </collision>
    <collision name="toe2_left">
      <origin rpy="0 1.5708 0" xyz="0.03 -0.015 -0.024"/>
      <geometry>
        <cylinder length="0.17" radius="0.015"/>
      </geometry>
    </collision>
  </link>
  <joint
    name="ankleRoll_Left"
    type="revolute">
    <origin
      xyz="0 0 0"
      rpy="0 0 0" />
    <parent
      link="footLeftY" />
    <child
      link="toe_left" />
    <axis
      xyz="1 0 0" />
   <limit effort="3.0" lower="-0.3491" upper="0.3491" velocity="20.0"/>
  </joint>
  <link
    name="hipRollRight">
    <inertial>
      <origin xyz="0.038363 -0.000079 -0.000669" rpy="0 0 0"/>
      <mass value="1.300114"/>
      <inertia ixx="0.001191" ixy="-0.000001" ixz="-0.000122" iyy="0.001273" iyz="-0.0000" izz="0.001434"/>
    </inertial>
    <visual>
      <origin
        xyz="0 0 0"
        rpy="0 0 0" />
      <geometry>
        <mesh
          filename="../meshes/r2.STL" />
      </geometry>
      <material
        name="">
        <color
          rgba="0.15 0.15 0.15 1" />
        <!-- <color
          rgba="0.75294 0.75294 0.75294 1" /> -->
      </material>
    </visual>
    <!-- <collision>
      <origin
        xyz="0 0 0"
        rpy="0 0 0" />
      <geometry>
        <mesh
          filename="../meshes/r2.STL" />
      </geometry>
    </collision> -->
  </link>
  <joint
    name="hipRoll_Right"
    type="revolute">
    <origin
      xyz="-0.048 -0.105 -0.0575"
      rpy="0 0 0" />
    <parent
      link="pelvis" />
    <child
      link="hipRollRight" />
    <axis
      xyz="1 0 0" />
    <limit effort="100.0" lower="-0.5236" upper="0.0873" velocity="8.0"/>
  </joint>
  <link
    name="hipYawRight">
    <inertial>
      <origin xyz="-0.000002 -0.044064 -0.085155" rpy="0 0 0"/>
      <mass value="3.946045"/>
      <inertia ixx="0.009075" ixy="0.000" ixz="-0.000029" iyy="0.014711" iyz="0.000457" izz="0.008308"/>
    </inertial>
    <visual>
      <origin
        xyz="0 0 0"
        rpy="0 0 0" />
      <geometry>
        <mesh
          filename="../meshes/r3.STL" />
      </geometry>
      <material
        name="">
        <color
          rgba="0.15 0.15 0.15 1" />
        <!-- <color
          rgba="0.752941176470588 0.752941176470588 0.752941176470588 1" /> -->
      </material>
    </visual>
    <!-- <collision>
      <origin
        xyz="0 0 0"
        rpy="0 0 0" />
      <geometry>
        <mesh
          filename="../meshes/r3.STL" />
      </geometry>
    </collision> -->
  </link>
  <joint
    name="hipYaw_Right"
    type="revolute">
    <origin
      xyz="0.048 0 -0.0415"
      rpy="0 0 0" />
    <parent
      link="hipRollRight" />
    <child
      link="hipYawRight" />
    <axis
      xyz="0 0 1" />
    <limit effort="82.5" lower="-0.3927" upper="0.3927" velocity="8.0"/>
  </joint>
  <link
    name="thigh_Right">
    <inertial>
      <origin xyz="0.001848 0.020822 -0.089529" rpy="0 0 0"/>
      <mass value="5.912408"/>
      <inertia ixx="0.066232" ixy="-0.000184" ixz="-0.000831" iyy="0.072898" iyz="0.005319" izz="0.012788"/>
    </inertial>
    <visual>
      <origin
        xyz="0 0 0"
        rpy="0 0 0" />
      <geometry>
        <mesh
          filename="../meshes/r4.STL" />
      </geometry>
      <material
        name="">
        <color
          rgba="0.15 0.15 0.15 1" />
        <!-- <color
          rgba="0.75294 0.75294 0.75294 1" /> -->
      </material>
    </visual>
    <!-- <collision>
      <origin
        xyz="0 0 0"
        rpy="0 0 0" />
      <geometry>
        <mesh
          filename="../meshes/r4.STL" />
      </geometry>
    </collision> -->
  </link>
  <joint
    name="hipPitch_Right"
    type="revolute">
    <origin
      xyz="0 0 -0.089"
      rpy="0 0 0" />
    <parent
      link="hipYawRight" />
    <child
      link="thigh_Right" />
    <axis
      xyz="0 1 0" />
    <limit effort="160.0" lower="-1.2217" upper="0.6981" velocity="15.0"/>
  </joint>
  <link
    name="shin_Right">
    <inertial>
      <origin xyz="-0.003249 -0.000089 -0.125655" rpy="0 0 0"/>
      <mass value="1.596833"/>
      <inertia ixx="0.012545" ixy="0.000006" ixz="0.000751" iyy="0.012925" iyz="-0.000128" izz="0.001146"/>
    </inertial>
    <visual>
      <origin
        xyz="0 0 0"
        rpy="0 0 0" />
      <geometry>
        <mesh
          filename="../meshes/r5.STL" />
      </geometry>
      <material
        name="">
        <color
          rgba="0.15 0.15 0.15 1" />
        <!-- <color
          rgba="0.75294 0.75294 0.75294 1" /> -->
      </material>
    </visual>
    <!-- <collision>
      <origin
        xyz="0 0 0"
        rpy="0 0 0" />
      <geometry>
        <mesh
          filename="../meshes/r5.STL" />
      </geometry>
    </collision> -->
  </link>
  <joint
    name="kneePitch_Right"
    type="revolute">
    <origin
      xyz="0 0 -0.36"
      rpy="0 0 0" />
    <parent
      link="thigh_Right" />
    <child
      link="shin_Right" />
    <axis
      xyz="0 1 0" />
    <limit effort="160.0" lower="-0.0873" upper="2.0944" velocity="15.0"/>
  </joint>
  <link
    name="footRightY">
    <inertial>
      <origin xyz="0 0 0" rpy="0 0 0"/>
      <mass value="0.08149923"/>
      <inertia ixx="0.00001092" ixy="0" ixz="0" iyy="0.00000851" iyz="0" izz=" 0.00001392"/>
    </inertial>
    <visual>
      <origin
        xyz="0 0 0"
        rpy="0 0 0" />
      <geometry>
        <mesh
          filename="../meshes/r6.STL" />
      </geometry>
      <material
        name="">
        <color
          rgba="0.15 0.15 0.15 1" />
        <!-- <color
          rgba="0.75294 0.75294 0.75294 1" /> -->
      </material>
    </visual>
    <!-- <collision>
      <origin
        xyz="0 0 0"
        rpy="0 0 0" />
      <geometry>
        <mesh
          filename="../meshes/r6.STL" />
      </geometry>
    </collision> -->
  </link>
  <joint
    name="anklePitch_Right"
    type="revolute">
    <origin
      xyz="0 0 -0.34"
      rpy="0 0 0" />
    <parent
      link="shin_Right" />
    <child
      link="footRightY" />
    <axis
      xyz="0 1 0" />
    <limit effort="8.0" lower="-1.0472" upper="0.5236" velocity="20.0"/>
  </joint>
  <link
    name="toe_right">
    <inertial>
      <origin xyz="0.014092 0.00000 -0.024641" rpy="0 0 0"/>
      <mass value="0.328269"/>
      <inertia ixx="0.000125" ixy="-0.0000" ixz="-0.000065" iyy="0.001089" iyz="-0.00000" izz="0.001152"/>
    </inertial>
    <visual>
      <origin
        xyz="0 0 0"
        rpy="0 0 0" />
      <geometry>
        <mesh
          filename="../meshes/r7.STL" />
      </geometry>
      <material
        name="">
        <color
          rgba="0.15 0.15 0.15 1" />
        <!-- <color
          rgba="0.752941176470588 0.752941176470588 0.752941176470588 1" /> -->
      </material>
    </visual>
    <!-- <collision>
      <origin
        xyz="0 0 0"
        rpy="0 0 0" />
      <geometry>
        <mesh
          filename="../meshes/r7.STL" />
      </geometry>
    </collision> -->
    <collision name="toe1_right">
      <origin rpy="0 1.5708 0" xyz="0.03 0.015 -0.024"/>
      <geometry>
        <cylinder length="0.17" radius="0.015"/>
      </geometry>
    </collision>
    <collision name="toe2_right">
      <origin rpy="0 1.5708 0" xyz="0.03 -0.015 -0.024"/>
      <geometry>
        <cylinder length="0.17" radius="0.015"/>
      </geometry>
    </collision>
  </link>
  <joint
    name="ankleRoll_Right"
    type="revolute">
    <origin
      xyz="0 0 0"
      rpy="0 0 0" />
    <parent
      link="footRightY" />
    <child
      link="toe_right" />
    <axis
      xyz="1 0 0" />
    <limit effort="3.0" lower="-0.3491" upper="0.3491" velocity="20.0"/>
  </joint>

  
  <link
    name="waistYaw">
    <inertial>
      <origin
        xyz="-0.010388 -0.001695 0.022471"
        rpy="0 0 0" />
      <mass
        value="0.378860" />
      <inertia
        ixx="0.000559"
        ixy="-0.000010"
        ixz="-0.000002"
        iyy="0.000414"
        iyz="-0.000027"
        izz="0.000713" />
    </inertial>
    <visual>
      <origin
        xyz="0 0 0"
        rpy="0 0 0" />
      <geometry>
        <mesh
          filename="../meshes/y3.STL" />
      </geometry>
      <material
        name="">
        <color
          rgba="0.15 0.15 0.15 1" />
        <!-- <color
          rgba="1 1 1 1" /> -->
      </material>
    </visual>
    <!-- <collision>
      <origin
        xyz="0 0 0"
        rpy="0 0 0" />
      <geometry>
        <mesh
          filename="../meshes/y3.STL" />
      </geometry>
    </collision> -->
  </link>
  <joint
    name="waistYaw"
    type="revolute">
    <origin
      xyz="0 0 0.0065"
      rpy="0 0 0" />
    <parent
      link="pelvis" />
    <child
      link="waistYaw" />
    <axis
      xyz="0 0 1" />
    <limit effort="82.5" lower="-0.7854" upper="0.7854" velocity="8.0"/>
  </joint>
  <link
    name="waistPitch">
    <inertial>
      <origin
        xyz="0.001679 0.037972 0.042537"
        rpy="0 0 0" />
      <mass
        value="2.453693" />
      <inertia
        ixx="0.006530"
        ixy="0.000007"
        ixz="0.000170"
        iyy="0.006528"
        iyz="0.000177"
        izz="0.002075" />
    </inertial>
    <visual>
      <origin
        xyz="0 0 0"
        rpy="0 0 0" />
      <geometry>
        <mesh
          filename="../meshes/y2.STL" />
      </geometry>
      <material
        name="">
        <color
          rgba="0.15 0.15 0.15 1" />
        <!-- <color
          rgba="0.686274509803922 0.686274509803922 0.686274509803922 1" /> -->
      </material>
    </visual>
    <!-- <collision>
      <origin
        xyz="0 0 0"
        rpy="0 0 0" />
      <geometry>
        <mesh
          filename="../meshes/y2.STL" />
      </geometry>
    </collision> -->
  </link>
  <joint
    name="waistPitch"
    type="revolute">
    <origin
      xyz="0 -0.03965 0.055"
      rpy="0 0 0" />
    <parent
      link="waistYaw" />
    <child
      link="waistPitch" />
    <axis
      xyz="0 1 0" />
    <limit effort="82.5" lower="-1.57" upper="1.57" velocity="8.0"/>
  </joint>
  <link
    name="waistRoll">
    <inertial>
      <origin
        xyz="-0.035884 0.0 0.032200"
        rpy="0 0 0" />
      <mass
        value="0.317200" />
      <inertia
        ixx="0.000344"
        ixy="0.0"
        ixz="-0.000015"
        iyy="0.000517"
        iyz="0.0"
        izz="0.000605" />
    </inertial>
    <visual>
      <origin
        xyz="0 0 0"
        rpy="0 0 0" />
      <geometry>
        <mesh
          filename="../meshes/y1.STL" />
      </geometry>
      <material
        name="">
        <color
          rgba="0.15 0.15 0.15 1" />
        <!-- <color
          rgba="0.752941176470588 0.752941176470588 0.752941176470588 1" /> -->
      </material>
    </visual>
    <!-- <collision>
      <origin
        xyz="0 0 0"
        rpy="0 0 0" />
      <geometry>
        <mesh
          filename="../meshes/y1.STL" />
      </geometry>
    </collision> -->
  </link>
  <joint
    name="waistRoll"
    type="revolute">
    <origin
      xyz="0.03965 0.03965 0.085"
      rpy="0 0 0" />
    <parent
      link="waistPitch" />
    <child
      link="waistRoll" />
    <axis
      xyz="1 0 0" />
    <limit effort="82.5" lower="-1.57" upper="1.57" velocity="8.0"/>
  </joint>
  <link
    name="torso">
    <inertial>
      <origin
        xyz="-0.012990 0.012559 -0.016876"
        rpy="0 0 0" />
      <mass
        value="5.293464" />
      <inertia
        ixx="0.031058"
        ixy="0.000699"
        ixz="0.002136"
        iyy="0.023216"
        iyz="0.001421"
        izz="0.016461" />
    </inertial>
    <visual>
      <origin
        xyz="0 0 0"
        rpy="0 0 0" />
      <geometry>
        <mesh
          filename="../meshes/b1.STL" />
      </geometry>
      <material
        name="">
        <color
          rgba="0.15 0.15 0.15 1" />
        <!-- <color
          rgba="0.752941176470588 0.752941176470588 0.752941176470588 1" /> -->
      </material>
    </visual>
    <collision>
      <origin
        xyz="0 0 0"
        rpy="0 0 0" />
      <geometry>
        <sphere radius="0.12"/>
        <!-- <mesh
          filename="../meshes/b1.STL" /> -->
      </geometry>
    </collision>
  </link>
  <joint
    name="torso"
    type="fixed">
    <origin
      xyz="-0.03965 0 0.19760320787506"
      rpy="0 0 0" />
    <parent
      link="waistRoll" />
    <child
      link="torso" />
    <axis
      xyz="1 0 0" />
  </joint>
  <link
    name="headYaw">
    <inertial>
      <origin
        xyz="0.00129639745850753 -6.9033527535535E-06 0.056235657168065"
        rpy="0 0 0" />
      <mass
        value="0.0717307740900392" />
      <inertia
        ixx="4.73353658590809E-05"
        ixy="-5.91807559537003E-09"
        ixz="-6.33450971236835E-06"
        iyy="5.0736400806054E-05"
        iyz="-3.00118139372468E-08"
        izz="2.89261642135794E-05" />
    </inertial>
    <visual>
      <origin
        xyz="0 0 0"
        rpy="0 0 0" />
      <geometry>
        <mesh
          filename="../meshes/t2.STL" />
      </geometry>
      <material
        name="">
        <color
          rgba="0.15 0.15 0.15 1" />
        <!-- <color
          rgba="0.752941176470588 0.752941176470588 0.752941176470588 1" /> -->
      </material>
    </visual>
    <!-- <collision>
      <origin
        xyz="0 0 0"
        rpy="0 0 0" />
      <geometry>
        <mesh
          filename="../meshes/t2.STL" />
      </geometry>
    </collision> -->
  </link>
  <joint
    name="headYaw"
    type="fixed">
    <origin
      xyz="0 0 0.146926485797641"
      rpy="0 0 0" />
    <parent
      link="torso" />
    <child
      link="headYaw" />
    <axis
      xyz="0 0 1" />
  </joint>
  <link
    name="headRoll">
    <inertial>
      <origin
        xyz="0.0208602830194603 0.00299722647897635 -0.00194684636960585"
        rpy="0 0 0" />
      <mass
        value="0.0189573884471622" />
      <inertia
        ixx="3.0726103076981E-06"
        ixy="4.10292482415322E-08"
        ixz="1.78312342311448E-08"
        iyy="5.66077119601757E-06"
        iyz="-1.51705009294056E-08"
        izz="3.71878352666774E-06" />
    </inertial>
    <visual>
      <origin
        xyz="0 0 0"
        rpy="0 0 0" />
      <geometry>
        <mesh
          filename="../meshes/t3.STL" />
      </geometry>
      <material
        name="">
        <color
          rgba="0.15 0.15 0.15 1" />
        <!-- <color
          rgba="0.752941176470588 0.752941176470588 0.752941176470588 1" /> -->
      </material>
    </visual>
    <!-- <collision>
      <origin
        xyz="0 0 0"
        rpy="0 0 0" />
      <geometry>
        <mesh
          filename="../meshes/t3.STL" />
      </geometry>
    </collision> -->
  </link>
  <joint
    name="headRoll"
    type="fixed">
    <origin
      xyz="-0.0214014957239914 0 0.122499738858556"
      rpy="0 0 0" />
    <parent
      link="headYaw" />
    <child
      link="headRoll" />
    <axis
      xyz="1 0 0" />
  </joint>
  <link
    name="headPitch">
    <inertial>
      <origin
        xyz="-2.31666208813652E-07 0.0210814390130442 0.0189749154507305"
        rpy="0 0 0" />
      <mass
        value="0.0106256456570579" />
      <inertia
        ixx="7.50496890616552E-06"
        ixy="4.71785743712524E-12"
        ixz="2.45834795723082E-11"
        iyy="3.56996332972272E-06"
        iyz="-3.86661746522976E-07"
        izz="5.49155423513382E-06" />
    </inertial>
    <visual>
      <origin
        xyz="0 0 0"
        rpy="0 0 0" />
      <geometry>
        <mesh
          filename="../meshes/t4.STL" />
      </geometry>
      <material
        name="">
        <color
          rgba="0.15 0.15 0.15 1" />
        <!-- <color
          rgba="1 1 1 1" /> -->
      </material>
    </visual>
    <!-- <collision>
      <origin
        xyz="0 0 0"
        rpy="0 0 0" />
      <geometry>
        <mesh
          filename="../meshes/t4.STL" />
      </geometry>
    </collision> -->
  </link>
  <joint
    name="headPitch"
    type="fixed">
    <origin
      xyz="0.0213999999984297 -0.0229999999638927 0"
      rpy="0 0 0" />
    <parent
      link="headRoll" />
    <child
      link="headPitch" />
    <axis
      xyz="0 1 0" />
  </joint>

  <link
    name="shoulderPitchLeft">
    <inertial>
      <origin
        xyz="0.00543959 0.05818666 -0.00001075"
        rpy="0 0 0" />
      <mass
        value="0.77170250" />
      <inertia
        ixx="0.00068500"
        ixy="0.00004059"
        ixz="0.00000064"
        iyy="0.00041017"
        iyz="-0.00000177"
        izz="0.00064509" />
    </inertial>
    <visual>
      <origin
        xyz="0 0 0"
        rpy="0 0 0" />
      <geometry>
        <mesh
          filename="../meshes/zuo1.STL" />
      </geometry>
      <material
        name="">
        <color
          rgba="0.15 0.15 0.15 1" />
        <!-- <color
          rgba="0.752941176470588 0.752941176470588 0.752941176470588 1" /> -->
      </material>
    </visual>
    <!-- <collision>
      <origin
        xyz="0 0 0"
        rpy="0 0 0" />
      <geometry>
        <mesh
          filename="../meshes/zuo1.STL" />
      </geometry>
    </collision> -->
  </link>
  <joint
    name="shoulderPitch_Left"
    type="revolute">
    <origin
      xyz="0 0.126623540681031 0.0196556705521279"
      rpy="0.436332320793253 0 0" />
    <parent
      link="torso" />
    <child
      link="shoulderPitchLeft" />
    <axis
      xyz="0 1 0" />
    <limit effort="18.0" lower="-2.618" upper="1.047" velocity="8.0"/>
  </joint>
  <link
    name="shoulderRollLeft">
    <inertial>
      <origin
        xyz="-0.02621271 0.09487288 0.03613994"
        rpy="0 0 0" />
      <mass
        value="0.50766554" />
      <inertia
        ixx="0.00092986"
        ixy="-0.00021876"
        ixz="-0.00006163"
        iyy="0.00032675"
        iyz="0.00017328"
        izz="0.00092647" />
    </inertial>
    <visual>
      <origin
        xyz="0 0 0"
        rpy="0 0 0" />
      <geometry>
        <mesh
          filename="../meshes/zuo2.STL" />
      </geometry>
      <material
        name="">
        <color
          rgba="0.15 0.15 0.15 1" />
        <!-- <color
          rgba="0.752941176470588 0.752941176470588 0.752941176470588 1" /> -->
      </material>
    </visual>
    <!-- <visual>
      <origin
        xyz="-0.025 0 0"
        rpy="0 0 0" />
      <geometry>
        <sphere radius="0.04"/>
      </geometry>
      <material
        name="">
        <color
          rgba="0.236 0.225 0.225 1" />
      </material>
    </visual> -->
    <collision>
      <origin
        xyz="-0.025 0 0"
        rpy="0 0 0" />
      <geometry>
        <sphere radius="0.04"/>
      </geometry>
      <!-- <origin
        xyz="0 0 0"
        rpy="0 0 0" />
      <geometry>
        <mesh
          filename="../meshes/zuo2.STL" />
      </geometry> -->
    </collision>
  </link>
  <joint
    name="shoulderRoll_Left"
    type="revolute">
    <origin
      xyz="0.031999983030471 0.0670000081048653 0"
      rpy="-2.00712863979338 0 0" />
    <parent
      link="shoulderPitchLeft" />
    <child
      link="shoulderRollLeft" />
    <axis
      xyz="1 0 0" />
    <limit effort="18.0" lower="0.0" upper="3.1415926" velocity="8.0"/>  
  </joint>
  <link
    name="shoulderYawLeft">
    <inertial>
      <origin
        xyz="-0.00058180 0.08646464 0.00051497"
        rpy="0 0 0" />
      <mass
        value="0.46974876" />
      <inertia
        ixx="0.00082642"
        ixy="-0.00000384"
        ixz="-0.00000177"
        iyy="0.00016793"
        iyz="0.00000332"
        izz="0.00081863" />
    </inertial>
    <visual>
      <origin
        xyz="0 0 0"
        rpy="0 0 0" />
      <geometry>
        <!-- <cylinder length="0.07" radius="0.015"/> -->
        <mesh
          filename="../meshes/zuo3.STL" />
      </geometry>
      <material
        name="">
        <color
          rgba="0.15 0.15 0.15 1" />
        <!-- <color
          rgba="0.752941176470588 0.752941176470588 0.752941176470588 1" /> -->
      </material>
    </visual>
    <collision>
      <origin
        xyz="0 0.05 0"
        rpy="1.57 0 0" />
      <geometry>
        <cylinder length="0.09" radius="0.03"/>
        <!-- <mesh
          filename="../meshes/zuo3.STL" /> -->
      </geometry>
      <!-- <origin
        xyz="0 0 0"
        rpy="0 0 0" />
      <geometry>
      
        <mesh
          filename="../meshes/zuo3.STL" />
      </geometry> -->
    </collision>
  </link>
  <joint
    name="shoulderYaw_Left"
    type="revolute">
    <origin
      xyz="-0.0320000087093567 0.13653033030089 0.0399999930319231"
      rpy="0 0 0" />
    <parent
      link="shoulderRollLeft" />
    <child
      link="shoulderYawLeft" />
    <axis
      xyz="0 1 0" />
    <limit effort="18.0" lower="-1.57" upper="1.57" velocity="8.0"/>
  </joint>
  <link
    name="elbowLeft">
    <inertial>
      <origin
        xyz="-0.00011118 0.08753807 -0.02085588"
        rpy="0 0 0" />
      <mass
        value="0.44695620" />
      <inertia
        ixx="0.00043623"
        ixy="-0.00000040"
        ixz="-0.00000006"
        iyy="0.00018512"
        iyz="-0.00005009"
        izz="0.00041190" />
    </inertial>
    <visual>
      <origin
        xyz="0 0 0"
        rpy="0 0 0" />
      <geometry>
        <mesh
          filename="../meshes/zuo4.STL" />
      </geometry>
      <material
        name="">
        <color
          rgba="0.15 0.15 0.15 1" />
        <!-- <color
          rgba="0.752941176470588 0.752941176470588 0.752941176470588 1" /> -->
      </material>
    </visual>
    <collision>
      <origin
        xyz="0 0.12 -0.02"
        rpy="1.57 0 0" />
      <geometry>
        <cylinder length="0.17" radius="0.035"/>
        <!-- <mesh
          filename="../meshes/zuo4.STL" /> -->
      </geometry>
      <!-- <origin
        xyz="0 0 0"
        rpy="0 0 0" />
      <geometry>
        <mesh
          filename="../meshes/zuo4.STL" />
      </geometry> -->
    </collision>
  </link>
  <joint
    name="elbow_Left"
    type="revolute">
    <origin
      xyz="0 0.109999999996649 0.0225303303019319"
      rpy="0 0 0" />
    <parent
      link="shoulderYawLeft" />
    <child
      link="elbowLeft" />
    <axis
      xyz="0 0 1" />
    <limit effort="18.0" lower="-2.8" upper="0.0" velocity="8.0"/>
  </joint>
  <link
    name="wristYawLeft">
    <inertial>
      <origin
        xyz="0.00001044 0.05580546 0.00019754"
        rpy="0 0 0" />
      <mass
        value="0.33817414" />
      <inertia
        ixx="0.00036885"
        ixy="0.00000004"
        ixz="0.00000003"
        iyy="0.00014206"
        iyz="0.00000171"
        izz="0.00032478" />
    </inertial>
    <visual>
      <origin
        xyz="0 0 0"
        rpy="0 0 0" />
      <geometry>
        <mesh
          filename="../meshes/zuo5.STL" />
      </geometry>
      <material
        name="">
        <color
          rgba="0.15 0.15 0.15 1" />
        <!-- <color
          rgba="0.752941176470588 0.752941176470588 0.752941176470588 1" /> -->
      </material>
    </visual>
    <!-- <collision>
      <origin
        xyz="0 0 0"
        rpy="0 0 0" />
      <geometry>
        <mesh
          filename="../meshes/zuo5.STL" />
      </geometry>
    </collision> -->
  </link>
  <joint
    name="wristYaw_Left"
    type="fixed">
    <origin
      xyz="0 0.119029693673247 -0.0225001718767759"
      rpy="1.22191583977987E-05 0 6.88165313456609E-05" />
    <parent
      link="elbowLeft" />
    <child
      link="wristYawLeft" />
    <axis
      xyz="0 1 0" />
  </joint>
  <link
    name="wristPitchLeft">
    <inertial>
      <origin
        xyz="0.00031583 -0.00130083 -0.02117234"
        rpy="0 0 0" />
      <mass
        value="0.17160000" />
      <inertia
        ixx="0.00003941"
        ixy="0.00000318"
        ixz="-0.00000006"
        iyy="0.00005228"
        iyz="0.00000014"
        izz="0.00005147" />
    </inertial>
    <visual>
      <origin
        xyz="0 0 0"
        rpy="0 0 0" />
      <geometry>
        <mesh
          filename="../meshes/zuo6.STL" />
      </geometry>
      <material
        name="">
        <color
          rgba="0.15 0.15 0.15 1" />
        <!-- <color
          rgba="0.752941176470588 0.752941176470588 0.752941176470588 1" /> -->
      </material>
    </visual>
    <!-- <collision>
      <origin
        xyz="0 0 0"
        rpy="0 0 0" />
      <geometry>
        <mesh
          filename="../meshes/zuo6.STL" />
      </geometry>
    </collision> -->
  </link>
  <joint
    name="wristPitch_Left"
    type="fixed">
    <origin
      xyz="0 0.122500000447922 0.0214000000000155"
      rpy="0 0 -6.88165313508023E-05" />
    <parent
      link="wristYawLeft" />
    <child
      link="wristPitchLeft" />
    <axis
      xyz="0 0 1" />
  </joint>
  <link
    name="wristRollLeft">
    <inertial>
      <origin
        xyz="-0.02108274 0.01897347 0.0"
        rpy="0 0 0" />
      <mass
        value="0.02868924" />
      <inertia
        ixx="0.00000964"
        ixy="-0.00000104"
        ixz="0.00000000"
        iyy="0.00001483"
        iyz="0.00000000"
        izz="0.00002026" />
    </inertial>
    <visual>
      <origin
        xyz="0 0 0"
        rpy="0 0 0" />
      <geometry>
        <mesh
          filename="../meshes/zuo7.STL" />
      </geometry>
      <material
        name="">
        <color
          rgba="0.15 0.15 0.15 1" />
        <!-- <color
          rgba="1 1 1 1" /> -->
      </material>
    </visual>
    <!-- <collision>
      <origin
        xyz="0 0 0"
        rpy="0 0 0" />
      <geometry>
        <mesh
          filename="../meshes/zuo7.STL" />
      </geometry>
    </collision> -->
  </link>
  <joint
    name="wristRoll_Left"
    type="fixed">
    <origin
      xyz="0.0229999999454974 0 -0.021400000000012"
      rpy="0 0 6.88165313172141E-05" />
    <parent
      link="wristPitchLeft" />
    <child
      link="wristRollLeft" />
    <axis
      xyz="1 0 0" />
  </joint>
  <link
    name="shoulderPitchRight">
    <inertial>
      <origin
        xyz="0.00524050 -0.05818589 -0.00000872"
        rpy="0 0 0" />
      <mass
        value="0.77170250" />
      <inertia
        ixx="0.00067837"
        ixy="-0.00003923"
        ixz="0.00000061"
        iyy="0.00040297"
        iyz="0.00000179"
        izz="0.00063796" />
    </inertial>
    <visual>
      <origin
        xyz="0 0 0"
        rpy="0 0 0" />
      <geometry>
        <mesh
          filename="../meshes/you1.STL" />
      </geometry>
      <material
        name="">
        <color
          rgba="0.15 0.15 0.15 1" />
        <!-- <color
          rgba="0.752941176470588 0.752941176470588 0.752941176470588 1" /> -->
      </material>
    </visual>
    <!-- <collision>
      <origin
        xyz="0 0 0"
        rpy="0 0 0" />
      <geometry>
        <mesh
          filename="../meshes/you1.STL" />
      </geometry>
    </collision> -->
  </link>
  <joint
    name="shoulderPitch_Right"
    type="revolute">
    <origin
      xyz="0 -0.126623540935121 0.0196556700072115"
      rpy="-0.43633231299858 0 0" />
    <parent
      link="torso" />
    <child
      link="shoulderPitchRight" />
    <axis
      xyz="0 1 0" />
    <limit effort="18.0" lower="-2.618" upper="1.047" velocity="8.0"/>
  </joint>
  <link
    name="shoulderRollRight">
    <inertial>
      <origin
        xyz="-0.02621258 -0.09483971 0.03613675"
        rpy="0 0 0" />
      <mass
        value="0.50766499" />
      <inertia
        ixx="0.00092464"
        ixy="0.00021867"
        ixz="-0.00006162"
        iyy="0.00032406"
        iyz="-0.00017321"
        izz="0.00092133" />
    </inertial>
    <visual>
      <origin
        xyz="0 0 0"
        rpy="0 0 0" />
      <geometry>
        <mesh
          filename="../meshes/you2.STL" />
      </geometry>
      <material
        name="">
        <color
          rgba="0.15 0.15 0.15 1" />
        <!-- <color
          rgba="0.752941176470588 0.752941176470588 0.752941176470588 1" /> -->
      </material>
    </visual>
    <collision>
      <origin
        xyz="-0.025 0 0"
        rpy="0 0 0" />
      <geometry>
        <sphere radius="0.04"/>
      </geometry>
      <!-- <origin
        xyz="0 0 0"
        rpy="0 0 0" />
      <geometry>
        <mesh
          filename="../meshes/you2.STL" />
      </geometry> -->
    </collision>
  </link>
  <joint
    name="shoulderRoll_Right"
    type="revolute">
    <origin
      xyz="0.0319999999999985 -0.0669999999999986 0"
      rpy="2.00712863979348 0 0" />
    <parent
      link="shoulderPitchRight" />
    <child
      link="shoulderRollRight" />
    <axis
      xyz="1 0 0" />
    <limit effort="18.0" lower="-3.1415926" upper="0.0" velocity="8.0"/>  
  </joint>
  <link
    name="shoulderYawRight">
    <inertial>
      <origin
        xyz="-0.00058316 -0.08646131 0.00047906"
        rpy="0 0 0" />
      <mass
        value="0.46974981" />
      <inertia
        ixx="0.00082183"
        ixy="0.00000387"
        ixz="-0.00000176"
        iyy="0.00016345"
        iyz="-0.00000294"
        izz="0.00081588" />
    </inertial>
    <visual>
      <origin
        xyz="0 0 0"
        rpy="0 0 0" />
      <geometry>
        <mesh
          filename="../meshes/you3.STL" />
      </geometry>
      <material
        name="">
        <color
          rgba="0.15 0.15 0.15 1" />
        <!-- <color
          rgba="0.752941176470588 0.752941176470588 0.752941176470588 1" /> -->
      </material>
    </visual>
    <collision>
      <origin
        xyz="0 -0.05 0"
        rpy="1.57 0 0" />
      <geometry>
        <cylinder length="0.09" radius="0.03"/>
        <!-- <mesh
          filename="../meshes/zuo3.STL" /> -->
      </geometry>
      <!-- <origin
        xyz="0 0 0"
        rpy="0 0 0" />
      <geometry>
        <mesh
          filename="../meshes/you3.STL" />
      </geometry> -->
    </collision>
  </link>
  <joint
    name="shoulderYaw_Right"
    type="revolute">
    <origin
      xyz="-0.0320000000002931 -0.136530330300864 0.0399999999991598"
      rpy="0 0 0" />
    <parent
      link="shoulderRollRight" />
    <child
      link="shoulderYawRight" />
    <axis
      xyz="0 1 0" />
    <limit effort="18.0" lower="-1.57" upper="1.57" velocity="8.0"/>
  </joint>
  <link
    name="elbowRight">
    <inertial>
      <origin
        xyz="-0.00010758 -0.08750034 -0.02085603"
        rpy="0 0 0" />
      <mass
        value="0.44695620" />
      <inertia
        ixx="0.00043144"
        ixy="0.00000041"
        ixz="-0.00000005"
        iyy="0.00018244"
        iyz="0.00005007"
        izz="0.00040705" />
    </inertial>
    <visual>
      <origin
        xyz="0 0 0"
        rpy="0 0 0" />
      <geometry>
        <mesh
          filename="../meshes/you4.STL" />
      </geometry>
      <material
        name="">
        <color
          rgba="0.15 0.15 0.15 1" />
        <!-- <color
          rgba="0.752941176470588 0.752941176470588 0.752941176470588 1" /> -->
      </material>
    </visual>
    <collision>
      <origin
        xyz="0 -0.12 -0.02"
        rpy="1.57 0 0" />
      <geometry>
        <cylinder length="0.17" radius="0.035"/>
        <!-- <mesh
          filename="../meshes/zuo4.STL" /> -->
      </geometry>
      <!-- <origin
        xyz="0 0 0"
        rpy="0 0 0" />
      <geometry>
        <mesh
          filename="../meshes/you4.STL" />
      </geometry> -->
    </collision>
  </link>
  <joint
    name="elbow_Right"
    type="revolute">
    <origin
      xyz="0 -0.109999999996644 0.0225303303019291"
      rpy="0 0 0" />
    <parent
      link="shoulderYawRight" />
    <child
      link="elbowRight" />
    <axis
      xyz="0 0 1" />
    <limit effort="18.0" lower="-0.0" upper="2.8" velocity="8.0"/>
  </joint>
  <link
    name="wristYawRight">
    <inertial>
      <origin
        xyz="-0.00000582 -0.05580865 -0.00010517"
        rpy="0 0 0" />
      <mass
        value="0.33817414" />
      <inertia
        ixx="0.00036777"
        ixy="0.00000006"
        ixz="-0.00000002"
        iyy="0.00014102"
        iyz="-0.00000257"
        izz="0.00032472" />
    </inertial>
    <visual>
      <origin
        xyz="0 0 0"
        rpy="0 0 0" />
      <geometry>
        <mesh
          filename="../meshes/you5.STL" />
      </geometry>
      <material
        name="">
        <color
          rgba="0.15 0.15 0.15 1" />
        <!-- <color
          rgba="0.752941176470588 0.752941176470588 0.752941176470588 1" /> -->
      </material>
    </visual>
    <!-- <collision>
      <origin
        xyz="0 0 0"
        rpy="0 0 0" />
      <geometry>
        <mesh
          filename="../meshes/you5.STL" />
      </geometry>
    </collision> -->
  </link>
  <joint
    name="wristYaw_Right"
    type="fixed">
    <origin
      xyz="0 -0.119029693672666 -0.0225001678683308"
      rpy="-1.22100046105742E-05 0 -6.83496138025266E-05" />
    <parent
      link="elbowRight" />
    <child
      link="wristYawRight" />
    <axis
      xyz="0 1 0" />
  </joint>
  <link
    name="wristPitchRight">
    <inertial>
      <origin
        xyz="-0.00102886 0.00129153 -0.02117405"
        rpy="0 0 0" />
      <mass
        value="0.17160000" />
      <inertia
        ixx="0.00003928"
        ixy="0.00000332"
        ixz="0.00000009"
        iyy="0.00004907"
        iyz="-0.00000014"
        izz="0.00004825" />
    </inertial>
    <visual>
      <origin
        xyz="0 0 0"
        rpy="0 0 0" />
      <geometry>
        <mesh
          filename="../meshes/you6.STL" />
      </geometry>
      <material
        name="">
        <color
          rgba="0.15 0.15 0.15 1" />
        <!-- <color
          rgba="0.752941176470588 0.752941176470588 0.752941176470588 1" /> -->
      </material>
    </visual>
    <!-- <collision>
      <origin
        xyz="0 0 0"
        rpy="0 0 0" />
      <geometry>
        <mesh
          filename="../meshes/you6.STL" />
      </geometry>
    </collision> -->
  </link>
  <joint
    name="wristPitch_Right"
    type="fixed">
    <origin
      xyz="0 -0.12250000044792 0.0214000000000172"
      rpy="0 0 0" />
    <parent
      link="wristYawRight" />
    <child
      link="wristPitchRight" />
    <axis
      xyz="0 0 1" />
  </joint>
  <link
    name="wristRollRight">
    <inertial>
      <origin
        xyz="0.02108274 -0.01897347 0.0"
        rpy="0 0 0" />
      <mass
        value="0.02868924" />
      <inertia
        ixx="0.00000964"
        ixy="-0.00000104"
        ixz="0.00000000"
        iyy="0.00001483"
        iyz="0.00000000"
        izz="0.00002026" />
    </inertial>
    <visual>
      <origin
        xyz="0 0 0"
        rpy="0 0 0" />
      <geometry>
        <mesh
          filename="../meshes/you7.STL" />
      </geometry>
      <material
        name="">
        <color
          rgba="0.15 0.15 0.15 1" />
        <!-- <color
          rgba="1 1 1 1" /> -->
      </material>
    </visual>
    <!-- <visual>
      <origin
        xyz="0.02 -0.02 0"
        rpy="0 -3.14 -1.0" />
      <geometry>
        <mesh
          filename="../meshes/gun_5.STL" />
        
      </geometry>
      <material
        name="">
        <color
          rgba="0.15 0.15 0.15 1" />
      </material>
    </visual> -->
    <!-- <visual>
      <origin
        xyz="0.2 -0.15 0"
        rpy="0 0 2.25" />
      <geometry>
        
        <box size="0.4 0.05 0.03"/>
      </geometry>
      <material
        name="">
        <color
          rgba="0.15 0.15 0.15 1" />
      </material>
    </visual> -->
    <!-- <visual>
      <origin
        xyz="0.22 -0.165 0"
        rpy="0 0 2.25" />
      <geometry>
        <box size="0.43 0.01 0.03"/>
      </geometry>
      <material
        name="">
        <color
          rgba="0.15 0.15 0.15 1" />
      </material>
    </visual>
    <visual>
      <origin
        xyz="0.04 -0. 0"
        rpy="0 0 2.5" />
      <geometry>
        <box size="0.15 0.05 0.01"/>
      </geometry>
      <material
        name="">
        <color
          rgba="0.15 0.15 0.15 1" />
      </material>
    </visual> -->
    <!-- <collision>
      <origin
        xyz="0 0 0"
        rpy="0 0 0" />
      <geometry>
        <mesh
          filename="../meshes/you7.STL" />
      </geometry>
    </collision> -->
  </link>
  <joint
    name="wristRoll_Right"
    type="fixed">
    <origin
      xyz="-0.023000000000045 0 -0.0213999999999737"
      rpy="0 0 0" />
    <parent
      link="wristPitchRight" />
    <child
      link="wristRollRight" />
    <axis
      xyz="1 0 0" />
  </joint>

  
</robot>
